Workbook

Sheet Hoja1
AL1: Cálculos:
A2: Red: | C2: 192 | D2: . | E2: 168 | F2: . | G2: 73 | H2: . | I2: 0 | J2: /24 | AL2: # de bits prestados = 6
F3: W | O3: X | W3: Y | AG3: Z | AL3: # Host por subred = 2
C5: 128 | D5: 64 | E5: 32 | F5: 16 | G5: 8 | H5: 4 | I5: 2 | J5: 1 | L5: 128 | M5: 64 | N5: 32 | O5: 16 | P5: 8 | Q5: 4 | R5: 2 | S5: 1 | U5: 128 | V5: 64 | W5: 32 | X5: 16 | Y5: 8 | Z5: 4 | AA5: 2 | AB5: 1 | AD5: 128 | AE5: 64 | AF5: 32 | AG5: 16 | AH5: 8 | AI5: 4 | AJ5: 2 | AK5: 1
C6: X | D6: X | E6: X | F6: X | G6: X | H6: X | I6: X | J6: X | L6: X | M6: X | N6: X | O6: X | P6: X | Q6: X | R6: X | S6: X | U6: X | V6: X | W6: X | X6: X | Y6: X | Z6: X | AA6: X | AB6: X | AD6: X | AE6: X | AF6: X | AG6: X | AH6: X | AI6: X | AJ6: X | AK6: X
A7: IP | C7: 1 | D7: 1 | E7: 0 | F7: 0 | G7: 0 | H7: 0 | I7: 0 | J7: 0 | L7: 1 | M7: 0 | N7: 1 | O7: 0 | P7: 1 | Q7: 0 | R7: 0 | S7: 0 | U7: 0 | V7: 1 | W7: 0 | X7: 0 | Y7: 1 | Z7: 0 | AA7: 0 | AB7: 1 | AD7: 0 | AE7: 0 | AF7: 0 | AG7: 0 | AH7: 0 | AI7: 0 | AJ7: 0 | AK7: 0
F8: 192 | O8: 168 | X8: 73 | AG8: 0
A9: MASK | C9: 1 | D9: 1 | E9: 1 | F9: 1 | G9: 1 | H9: 1 | I9: 1 | J9: 1 | L9: 1 | M9: 1 | N9: 1 | O9: 1 | P9: 1 | Q9: 1 | R9: 1 | S9: 1 | U9: 1 | V9: 1 | W9: 1 | X9: 1 | Y9: 1 | Z9: 1 | AA9: 1 | AB9: 1 | AD9: 1 | AE9: 1 | AF9: 1 | AG9: 1 | AH9: 1 | AI9: 1 | AJ9: 0 | AK9: 0 | AL9: (Máscara subred)
F10: 255 | O10: 255 | X10: 255 | AG10: 252
A11: AND | C11: 1 | D11: 1 | E11: 0 | F11: 0 | G11: 0 | H11: 0 | I11: 0 | J11: 0 | L11: 1 | M11: 0 | N11: 1 | O11: 0 | P11: 1 | Q11: 0 | R11: 0 | S11: 0 | U11: 0 | V11: 1 | W11: 0 | X11: 0 | Y11: 1 | Z11: 0 | AA11: 0 | AB11: 1 | AD11: 0 | AE11: 0 | AF11: 0 | AG11: 0 | AH11: 0 | AI11: 0 | AJ11: 0 | AK11: 0
AG12: 0
AG14: 0
A15: BROADCAST | C15: 1 | D15: 1 | E15: 0 | F15: 0 | G15: 0 | H15: 0 | I15: 0 | J15: 0 | L15: 1 | M15: 0 | N15: 1 | O15: 0 | P15: 1 | Q15: 0 | R15: 0 | S15: 0 | U15: 0 | V15: 1 | W15: 0 | X15: 0 | Y15: 1 | Z15: 0 | AA15: 0 | AB15: 1 | AD15: 0 | AE15: 0 | AF15: 0 | AG15: 0 | AH15: 0 | AI15: 0 | AJ15: 1 | AK15: 1 | AL15: 192.168.73.3/30
A17: subRED | F17: 192 | O17: 168 | X17: 73 | AM17: Host Disponibles
A18: 1 | C18: 1 | D18: 1 | E18: 0 | F18: 0 | G18: 0 | H18: 0 | I18: 0 | J18: 0 | L18: 1 | M18: 0 | N18: 1 | O18: 0 | P18: 1 | Q18: 0 | R18: 0 | S18: 0 | U18: 0 | V18: 1 | W18: 0 | X18: 0 | Y18: 1 | Z18: 0 | AA18: 0 | AB18: 1 | AD18: 0 | AE18: 0 | AF18: 0 | AG18: 0 | AH18: 0 | AI18: 0 | AJ18: 0 | AK18: 0 | AL18: ="192.168.73." & ((ROWS(Hoja1!$A$1:A1)-1)*4) & "/30 " & "Rango: 192.168.73." & ((ROWS(Hoja1!$A$1:A1)-1)*4 + 1) & " - " & "192.168.73." & ((ROWS(Hoja1!$A$1:A1)-1)*4 + 2) & " Broadcast: 192.168.73." & ((ROWS(Hoja1!$A$1:A1)-1)*4 + 3) -> 192.168.73.0/30 Rango: 192.168.73.1 - 192.168.73.2 Broadcast: 192.168.73.3 | AM18: 2
A19: =A18+1 -> 2 | C19: 1 | D19: 1 | E19: 0 | F19: 0 | G19: 0 | H19: 0 | I19: 0 | J19: 0 | L19: 1 | M19: 0 | N19: 1 | O19: 0 | P19: 1 | Q19: 0 | R19: 0 | S19: 0 | U19: 0 | V19: 1 | W19: 0 | X19: 0 | Y19: 1 | Z19: 0 | AA19: 0 | AB19: 1 | AD19: 0 | AE19: 0 | AF19: 0 | AG19: 0 | AH19: 0 | AI19: 1 | AJ19: 0 | AK19: 0 | AL19: ="192.168.73." & ((ROWS(Hoja1!$A$1:A2)-1)*4) & "/30 " & "Rango: 192.168.73." & ((ROWS(Hoja1!$A$1:A2)-1)*4 + 1) & " - " & "192.168.73." & ((ROWS(Hoja1!$A$1:A2)-1)*4 + 2) & " Broadcast: 192.168.73." & ((ROWS(Hoja1!$A$1:A2)-1)*4 + 3) -> 192.168.73.4/30 Rango: 192.168.73.5 - 192.168.73.6 Broadcast: 192.168.73.7 | AM19: 2
A20: =A19+1 -> 3 | C20: 1 | D20: 1 | E20: 0 | F20: 0 | G20: 0 | H20: 0 | I20: 0 | J20: 0 | L20: 1 | M20: 0 | N20: 1 | O20: 0 | P20: 1 | Q20: 0 | R20: 0 | S20: 0 | U20: 0 | V20: 1 | W20: 0 | X20: 0 | Y20: 1 | Z20: 0 | AA20: 0 | AB20: 1 | AD20: 0 | AE20: 0 | AF20: 0 | AG20: 0 | AH20: 1 | AI20: 0 | AJ20: 0 | AK20: 0 | AL20: ="192.168.73." & ((ROWS(Hoja1!$A$1:A3)-1)*4) & "/30 " & "Rango: 192.168.73." & ((ROWS(Hoja1!$A$1:A3)-1)*4 + 1) & " - " & "192.168.73." & ((ROWS(Hoja1!$A$1:A3)-1)*4 + 2) & " Broadcast: 192.168.73." & ((ROWS(Hoja1!$A$1:A3)-1)*4 + 3) -> 192.168.73.8/30 Rango: 192.168.73.9 - 192.168.73.10 Broadcast: 192.168.73.11 | AM20: 2
A21: =A20+1 -> 4 | C21: 1 | D21: 1 | E21: 0 | F21: 0 | G21: 0 | H21: 0 | I21: 0 | J21: 0 | L21: 1 | M21: 0 | N21: 1 | O21: 0 | P21: 1 | Q21: 0 | R21: 0 | S21: 0 | U21: 0 | V21: 1 | W21: 0 | X21: 0 | Y21: 1 | Z21: 0 | AA21: 0 | AB21: 1 | AD21: 0 | AE21: 0 | AF21: 0 | AG21: 0 | AH21: 1 | AI21: 1 | AJ21: 0 | AK21: 0 | AL21: ="192.168.73." & ((ROWS(Hoja1!$A$1:A4)-1)*4) & "/30 " & "Rango: 192.168.73." & ((ROWS(Hoja1!$A$1:A4)-1)*4 + 1) & " - " & "192.168.73." & ((ROWS(Hoja1!$A$1:A4)-1)*4 + 2) & " Broadcast: 192.168.73." & ((ROWS(Hoja1!$A$1:A4)-1)*4 + 3) -> 192.168.73.12/30 Rango: 192.168.73.13 - 192.168.73.14 Broadcast: 192.168.73.15 | AM21: 2
A22: =A21+1 -> 5 | C22: 1 | D22: 1 | E22: 0 | F22: 0 | G22: 0 | H22: 0 | I22: 0 | J22: 0 | L22: 1 | M22: 0 | N22: 1 | O22: 0 | P22: 1 | Q22: 0 | R22: 0 | S22: 0 | U22: 0 | V22: 1 | W22: 0 | X22: 0 | Y22: 1 | Z22: 0 | AA22: 0 | AB22: 1 | AD22: 0 | AE22: 0 | AF22: 0 | AG22: 1 | AH22: 0 | AI22: 0 | AJ22: 0 | AK22: 0 | AL22: ="192.168.73." & ((ROWS(Hoja1!$A$1:A5)-1)*4) & "/30 " & "Rango: 192.168.73." & ((ROWS(Hoja1!$A$1:A5)-1)*4 + 1) & " - " & "192.168.73." & ((ROWS(Hoja1!$A$1:A5)-1)*4 + 2) & " Broadcast: 192.168.73." & ((ROWS(Hoja1!$A$1:A5)-1)*4 + 3) -> 192.168.73.16/30 Rango: 192.168.73.17 - 192.168.73.18 Broadcast: 192.168.73.19 | AM22: 2
A23: =A22+1 -> 6 | C23: 1 | D23: 1 | E23: 0 | F23: 0 | G23: 0 | H23: 0 | I23: 0 | J23: 0 | L23: 1 | M23: 0 | N23: 1 | O23: 0 | P23: 1 | Q23: 0 | R23: 0 | S23: 0 | U23: 0 | V23: 1 | W23: 0 | X23: 0 | Y23: 1 | Z23: 0 | AA23: 0 | AB23: 1 | AD23: 0 | AE23: 0 | AF23: 0 | AG23: 1 | AH23: 0 | AI23: 1 | AJ23: 0 | AK23: 0 | AL23: ="192.168.73." & ((ROWS(Hoja1!$A$1:A6)-1)*4) & "/30 " & "Rango: 192.168.73." & ((ROWS(Hoja1!$A$1:A6)-1)*4 + 1) & " - " & "192.168.73." & ((ROWS(Hoja1!$A$1:A6)-1)*4 + 2) & " Broadcast: 192.168.73." & ((ROWS(Hoja1!$A$1:A6)-1)*4 + 3) -> 192.168.73.20/30 Rango: 192.168.73.21 - 192.168.73.22 Broadcast: 192.168.73.23 | AM23: 2
A24: =A23+1 -> 7 | C24: 1 | D24: 1 | E24: 0 | F24: 0 | G24: 0 | H24: 0 | I24: 0 | J24: 0 | L24: 1 | M24: 0 | N24: 1 | O24: 0 | P24: 1 | Q24: 0 | R24: 0 | S24: 0 | U24: 0 | V24: 1 | W24: 0 | X24: 0 | Y24: 1 | Z24: 0 | AA24: 0 | AB24: 1 | AD24: 0 | AE24: 0 | AF24: 0 | AG24: 1 | AH24: 1 | AI24: 0 | AJ24: 0 | AK24: 0 | AL24: ="192.168.73." & ((ROWS(Hoja1!$A$1:A7)-1)*4) & "/30 " & "Rango: 192.168.73." & ((ROWS(Hoja1!$A$1:A7)-1)*4 + 1) & " - " & "192.168.73." & ((ROWS(Hoja1!$A$1:A7)-1)*4 + 2) & " Broadcast: 192.168.73." & ((ROWS(Hoja1!$A$1:A7)-1)*4 + 3) -> 192.168.73.24/30 Rango: 192.168.73.25 - 192.168.73.26 Broadcast: 192.168.73.27 | AM24: 2
A25: =A24+1 -> 8 | C25: 1 | D25: 1 | E25: 0 | F25: 0 | G25: 0 | H25: 0 | I25: 0 | J25: 0 | L25: 1 | M25: 0 | N25: 1 | O25: 0 | P25: 1 | Q25: 0 | R25: 0 | S25: 0 | U25: 0 | V25: 1 | W25: 0 | X25: 0 | Y25: 1 | Z25: 0 | AA25: 0 | AB25: 1 | AD25: 0 | AE25: 0 | AF25: 0 | AG25: 1 | AH25: 1 | AI25: 1 | AJ25: 0 | AK25: 0 | AL25: ="192.168.73." & ((ROWS(Hoja1!$A$1:A8)-1)*4) & "/30 " & "Rango: 192.168.73." & ((ROWS(Hoja1!$A$1:A8)-1)*4 + 1) & " - " & "192.168.73." & ((ROWS(Hoja1!$A$1:A8)-1)*4 + 2) & " Broadcast: 192.168.73." & ((ROWS(Hoja1!$A$1:A8)-1)*4 + 3) -> 192.168.73.28/30 Rango: 192.168.73.29 - 192.168.73.30 Broadcast: 192.168.73.31 | AM25: 2
A26: =A25+1 -> 9 | C26: 1 | D26: 1 | E26: 0 | F26: 0 | G26: 0 | H26: 0 | I26: 0 | J26: 0 | L26: 1 | M26: 0 | N26: 1 | O26: 0 | P26: 1 | Q26: 0 | R26: 0 | S26: 0 | U26: 0 | V26: 1 | W26: 0 | X26: 0 | Y26: 1 | Z26: 0 | AA26: 0 | AB26: 1 | AD26: 0 | AE26: 0 | AF26: 1 | AG26: 0 | AH26: 0 | AI26: 0 | AJ26: 0 | AK26: 0 | AL26: ="192.168.73." & ((ROWS(Hoja1!$A$1:A9)-1)*4) & "/30 " & "Rango: 192.168.73." & ((ROWS(Hoja1!$A$1:A9)-1)*4 + 1) & " - " & "192.168.73." & ((ROWS(Hoja1!$A$1:A9)-1)*4 + 2) & " Broadcast: 192.168.73." & ((ROWS(Hoja1!$A$1:A9)-1)*4 + 3) -> 192.168.73.32/30 Rango: 192.168.73.33 - 192.168.73.34 Broadcast: 192.168.73.35 | AM26: 2
A27: =A26+1 -> 10 | C27: 1 | D27: 1 | E27: 0 | F27: 0 | G27: 0 | H27: 0 | I27: 0 | J27: 0 | L27: 1 | M27: 0 | N27: 1 | O27: 0 | P27: 1 | Q27: 0 | R27: 0 | S27: 0 | U27: 0 | V27: 1 | W27: 0 | X27: 0 | Y27: 1 | Z27: 0 | AA27: 0 | AB27: 1 | AD27: 0 | AE27: 0 | AF27: 1 | AG27: 0 | AH27: 0 | AI27: 1 | AJ27: 0 | AK27: 0 | AL27: ="192.168.73." & ((ROWS(Hoja1!$A$1:A10)-1)*4) & "/30 " & "Rango: 192.168.73." & ((ROWS(Hoja1!$A$1:A10)-1)*4 + 1) & " - " & "192.168.73." & ((ROWS(Hoja1!$A$1:A10)-1)*4 + 2) & " Broadcast: 192.168.73." & ((ROWS(Hoja1!$A$1:A10)-1)*4 + 3) -> 192.168.73.36/30 Rango: 192.168.73.37 - 192.168.73.38 Broadcast: 192.168.73.39 | AM27: 2
A28: =A27+1 -> 11 | C28: 1 | D28: 1 | E28: 0 | F28: 0 | G28: 0 | H28: 0 | I28: 0 | J28: 0 | L28: 1 | M28: 0 | N28: 1 | O28: 0 | P28: 1 | Q28: 0 | R28: 0 | S28: 0 | U28: 0 | V28: 1 | W28: 0 | X28: 0 | Y28: 1 | Z28: 0 | AA28: 0 | AB28: 1 | AD28: 0 | AE28: 0 | AF28: 1 | AG28: 0 | AH28: 1 | AI28: 0 | AJ28: 0 | AK28: 0 | AL28: ="192.168.73." & ((ROWS(Hoja1!$A$1:A11)-1)*4) & "/30 " & "Rango: 192.168.73." & ((ROWS(Hoja1!$A$1:A11)-1)*4 + 1) & " - " & "192.168.73." & ((ROWS(Hoja1!$A$1:A11)-1)*4 + 2) & " Broadcast: 192.168.73." & ((ROWS(Hoja1!$A$1:A11)-1)*4 + 3) -> 192.168.73.40/30 Rango: 192.168.73.41 - 192.168.73.42 Broadcast: 192.168.73.43 | AM28: 2
A29: =A28+1 -> 12 | C29: 1 | D29: 1 | E29: 0 | F29: 0 | G29: 0 | H29: 0 | I29: 0 | J29: 0 | L29: 1 | M29: 0 | N29: 1 | O29: 0 | P29: 1 | Q29: 0 | R29: 0 | S29: 0 | U29: 0 | V29: 1 | W29: 0 | X29: 0 | Y29: 1 | Z29: 0 | AA29: 0 | AB29: 1 | AD29: 0 | AE29: 0 | AF29: 1 | AG29: 0 | AH29: 1 | AI29: 1 | AJ29: 0 | AK29: 0 | AL29: ="192.168.73." & ((ROWS(Hoja1!$A$1:A12)-1)*4) & "/30 " & "Rango: 192.168.73." & ((ROWS(Hoja1!$A$1:A12)-1)*4 + 1) & " - " & "192.168.73." & ((ROWS(Hoja1!$A$1:A12)-1)*4 + 2) & " Broadcast: 192.168.73." & ((ROWS(Hoja1!$A$1:A12)-1)*4 + 3) -> 192.168.73.44/30 Rango: 192.168.73.45 - 192.168.73.46 Broadcast: 192.168.73.47 | AM29: 2
A30: =A29+1 -> 13 | C30: 1 | D30: 1 | E30: 0 | F30: 0 | G30: 0 | H30: 0 | I30: 0 | J30: 0 | L30: 1 | M30: 0 | N30: 1 | O30: 0 | P30: 1 | Q30: 0 | R30: 0 | S30: 0 | U30: 0 | V30: 1 | W30: 0 | X30: 0 | Y30: 1 | Z30: 0 | AA30: 0 | AB30: 1 | AD30: 0 | AE30: 0 | AF30: 1 | AG30: 1 | AH30: 0 | AI30: 0 | AJ30: 0 | AK30: 0 | AL30: ="192.168.73." & ((ROWS(Hoja1!$A$1:A13)-1)*4) & "/30 " & "Rango: 192.168.73." & ((ROWS(Hoja1!$A$1:A13)-1)*4 + 1) & " - " & "192.168.73." & ((ROWS(Hoja1!$A$1:A13)-1)*4 + 2) & " Broadcast: 192.168.73." & ((ROWS(Hoja1!$A$1:A13)-1)*4 + 3) -> 192.168.73.48/30 Rango: 192.168.73.49 - 192.168.73.50 Broadcast: 192.168.73.51 | AM30: 2
... A47: =A46+1 -> 30 | C47: 1 | D47: 1 | E47: 0 | F47: 0 | G47: 0 | H47: 0 | I47: 0 | J47: 0 | L47: 1 | M47: 0 | N47: 1 | O47: 0 | P47: 1 | Q47: 0 | R47: 0 | S47: 0 | U47: 0 | V47: 1 | W47: 0 | X47: 0 | Y47: 1 | Z47: 0 | AA47: 0 | AB47: 1 | AD47: 0 | AE47: 1 | AF47: 1 | AG47: 1 | AH47: 0 | AI47: 1 | AJ47: 0 | AK47: 0 | AL47: ="192.168.73." & ((ROWS(Hoja1!$A$1:A30)-1)*4) & "/30 " & "Rango: 192.168.73." & ((ROWS(Hoja1!$A$1:A30)-1)*4 + 1) & " - " & "192.168.73." & ((ROWS(Hoja1!$A$1:A30)-1)*4 + 2) & " Broadcast: 192.168.73." & ((ROWS(Hoja1!$A$1:A30)-1)*4 + 3) -> 192.168.73.116/30 Rango: 192.168.73.117 - 192.168.73.118 Broadcast: 192.168.73.119 | AM47: 2
A48: 31 | C48: 1 | D48: 1 | E48: 0 | F48: 0 | G48: 0 | H48: 0 | I48: 0 | J48: 0 | L48: 1 | M48: 0 | N48: 1 | O48: 0 | P48: 1 | Q48: 0 | R48: 0 | S48: 0 | U48: 0 | V48: 1 | W48: 0 | X48: 0 | Y48: 1 | Z48: 0 | AA48: 0 | AB48: 1 | AD48: 0 | AE48: 1 | AF48: 1 | AG48: 1 | AH48: 1 | AI48: 0 | AJ48: 0 | AK48: 0 | AL48: 192.168.73.120/29 Rango: 192.168.73.121 - 192.168.73.126 Broadcast: 192.168.73.127 | AM48: 6
C49: 1 | D49: 1 | E49: 0 | F49: 0 | G49: 0 | H49: 0 | I49: 0 | J49: 0 | L49: 1 | M49: 0 | N49: 1 | O49: 0 | P49: 1 | Q49: 0 | R49: 0 | S49: 0 | U49: 0 | V49: 1 | W49: 0 | X49: 0 | Y49: 1 | Z49: 0 | AA49: 0 | AB49: 1 | AD49: 0 | AE49: 1 | AF49: 1 | AG49: 1 | AH49: 1 | AI49: 1 | AJ49: 0 | AK49: 0
A50: 32 | C50: 1 | D50: 1 | E50: 0 | F50: 0 | G50: 0 | H50: 0 | I50: 0 | J50: 0 | L50: 1 | M50: 0 | N50: 1 | O50: 0 | P50: 1 | Q50: 0 | R50: 0 | S50: 0 | U50: 0 | V50: 1 | W50: 0 | X50: 0 | Y50: 1 | Z50: 0 | AA50: 0 | AB50: 1 | AD50: 1 | AE50: 0 | AF50: 0 | AG50: 0 | AH50: 0 | AI50: 0 | AJ50: 0 | AK50: 0 | AL50: 192.168.73.128/28 Rango: 192.168.73.129 - 192.168.73.142 Broadcast: 192.168.73.143 | AM50: 14
C51: 1 | D51: 1 | E51: 0 | F51: 0 | G51: 0 | H51: 0 | I51: 0 | J51: 0 | L51: 1 | M51: 0 | N51: 1 | O51: 0 | P51: 1 | Q51: 0 | R51: 0 | S51: 0 | U51: 0 | V51: 1 | W51: 0 | X51: 0 | Y51: 1 | Z51: 0 | AA51: 0 | AB51: 1 | AD51: 1 | AE51: 0 | AF51: 0 | AG51: 0 | AH51: 0 | AI51: 1 | AJ51: 0 | AK51: 0
C52: 1 | D52: 1 | E52: 0 | F52: 0 | G52: 0 | H52: 0 | I52: 0 | J52: 0 | L52: 1 | M52: 0 | N52: 1 | O52: 0 | P52: 1 | Q52: 0 | R52: 0 | S52: 0 | U52: 0 | V52: 1 | W52: 0 | X52: 0 | Y52: 1 | Z52: 0 | AA52: 0 | AB52: 1 | AD52: 1 | AE52: 0 | AF52: 0 | AG52: 0 | AH52: 1 | AI52: 0 | AJ52: 0 | AK52: 0
C53: 1 | D53: 1 | E53: 0 | F53: 0 | G53: 0 | H53: 0 | I53: 0 | J53: 0 | L53: 1 | M53: 0 | N53: 1 | O53: 0 | P53: 1 | Q53: 0 | R53: 0 | S53: 0 | U53: 0 | V53: 1 | W53: 0 | X53: 0 | Y53: 1 | Z53: 0 | AA53: 0 | AB53: 1 | AD53: 1 | AE53: 0 | AF53: 0 | AG53: 0 | AH53: 1 | AI53: 1 | AJ53: 0 | AK53: 0
A54: 33 | C54: 1 | D54: 1 | E54: 0 | F54: 0 | G54: 0 | H54: 0 | I54: 0 | J54: 0 | L54: 1 | M54: 0 | N54: 1 | O54: 0 | P54: 1 | Q54: 0 | R54: 0 | S54: 0 | U54: 0 | V54: 1 | W54: 0 | X54: 0 | Y54: 1 | Z54: 0 | AA54: 0 | AB54: 1 | AD54: 1 | AE54: 0 | AF54: 0 | AG54: 1 | AH54: 0 | AI54: 0 | AJ54: 0 | AK54: 0 | AL54: 192.168.73.144/28 Rango: 192.168.73.145 - 192.168.73.158 Broadcast: 192.168.73.159 | AM54: 14
C55: 1 | D55: 1 | E55: 0 | F55: 0 | G55: 0 | H55: 0 | I55: 0 | J55: 0 | L55: 1 | M55: 0 | N55: 1 | O55: 0 | P55: 1 | Q55: 0 | R55: 0 | S55: 0 | U55: 0 | V55: 1 | W55: 0 | X55: 0 | Y55: 1 | Z55: 0 | AA55: 0 | AB55: 1 | AD55: 1 | AE55: 0 | AF55: 0 | AG55: 1 | AH55: 0 | AI55: 1 | AJ55: 0 | AK55: 0
C56: 1 | D56: 1 | E56: 0 | F56: 0 | G56: 0 | H56: 0 | I56: 0 | J56: 0 | L56: 1 | M56: 0 | N56: 1 | O56: 0 | P56: 1 | Q56: 0 | R56: 0 | S56: 0 | U56: 0 | V56: 1 | W56: 0 | X56: 0 | Y56: 1 | Z56: 0 | AA56: 0 | AB56: 1 | AD56: 1 | AE56: 0 | AF56: 0 | AG56: 1 | AH56: 1 | AI56: 0 | AJ56: 0 | AK56: 0
C57: 1 | D57: 1 | E57: 0 | F57: 0 | G57: 0 | H57: 0 | I57: 0 | J57: 0 | L57: 1 | M57: 0 | N57: 1 | O57: 0 | P57: 1 | Q57: 0 | R57: 0 | S57: 0 | U57: 0 | V57: 1 | W57: 0 | X57: 0 | Y57: 1 | Z57: 0 | AA57: 0 | AB57: 1 | AD57: 1 | AE57: 0 | AF57: 0 | AG57: 1 | AH57: 1 | AI57: 1 | AJ57: 0 | AK57: 0
A58: 34 | C58: 1 | D58: 1 | E58: 0 | F58: 0 | G58: 0 | H58: 0 | I58: 0 | J58: 0 | L58: 1 | M58: 0 | N58: 1 | O58: 0 | P58: 1 | Q58: 0 | R58: 0 | S58: 0 | U58: 0 | V58: 1 | W58: 0 | X58: 0 | Y58: 1 | Z58: 0 | AA58: 0 | AB58: 1 | AD58: 1 | AE58: 0 | AF58: 1 | AG58: 0 | AH58: 0 | AI58: 0 | AJ58: 0 | AK58: 0 | AL58: 192.168.73.160/27 Rango: 192.168.73.161 - 192.168.73.190 Broadcast: 192.168.73.191 | AM58: 30
C59: 1 | D59: 1 | E59: 0 | F59: 0 | G59: 0 | H59: 0 | I59: 0 | J59: 0 | L59: 1 | M59: 0 | N59: 1 | O59: 0 | P59: 1 | Q59: 0 | R59: 0 | S59: 0 | U59: 0 | V59: 1 | W59: 0 | X59: 0 | Y59: 1 | Z59: 0 | AA59: 0 | AB59: 1 | AD59: 1 | AE59: 0 | AF59: 1 | AG59: 0 | AH59: 0 | AI59: 1 | AJ59: 0 | AK59: 0
...
